2025-07-21 19:13:01,142 ERROR: Unhandled Exception: (sqlite3.OperationalError) no such column: expertise_reports.report_id
[SQL: SELECT expertise_reports.id AS expertise_reports_id, expertise_reports.report_id AS expertise_reports_report_id, expertise_reports.expertise_type_id AS expertise_reports_expertise_type_id, expertise_reports.comment AS expertise_reports_comment 
FROM expertise_reports 
WHERE expertise_reports.expertise_type_id IN (?, ?, ?)]
[parameters: (1, 2, 3)]
(Background on this error at: https://sqlalche.me/e/20/e3q8) [in /mnt/c/Users/Killua/Desktop/Vehicle-Inspection-Web-App-main/app/routes/errors.py:36]
2025-07-21 20:08:59,784 ERROR: Unhandled Exception: 'Staff' object has no attribute 'full_name' [in /mnt/c/Users/Killua/Desktop/Vehicle-Inspection-Web-App-main/app/routes/errors.py:36]
2025-07-21 20:09:17,164 ERROR: Unhandled Exception: 'Staff' object has no attribute 'full_name' [in /mnt/c/Users/Killua/Desktop/Vehicle-Inspection-Web-App-main/app/routes/errors.py:36]
2025-07-21 23:40:39,055 ERROR: Exception on /report/add [GET] [in /mnt/c/Users/Killua/Desktop/Vehicle-Inspection-Web-App-main/.venv/lib/python3.10/site-packages/flask/app.py:838]
Traceback (most recent call last):
  File "/mnt/c/Users/Killua/Desktop/Vehicle-Inspection-Web-App-main/.venv/lib/python3.10/site-packages/flask/app.py", line 1473, in wsgi_app
    response = self.full_dispatch_request()
  File "/mnt/c/Users/Killua/Desktop/Vehicle-Inspection-Web-App-main/.venv/lib/python3.10/site-packages/flask/app.py", line 883, in full_dispatch_request
    return self.finalize_request(rv)
  File "/mnt/c/Users/Killua/Desktop/Vehicle-Inspection-Web-App-main/.venv/lib/python3.10/site-packages/flask/app.py", line 902, in finalize_request
    response = self.make_response(rv)
  File "/mnt/c/Users/Killua/Desktop/Vehicle-Inspection-Web-App-main/.venv/lib/python3.10/site-packages/flask/app.py", line 1174, in make_response
    raise TypeError(
TypeError: The view function for 'reports.add_report' did not return a valid response. The function either returned None or ended without a return statement.
2025-07-21 23:41:22,893 ERROR: Exception on /report/add [GET] [in /mnt/c/Users/Killua/Desktop/Vehicle-Inspection-Web-App-main/.venv/lib/python3.10/site-packages/flask/app.py:838]
Traceback (most recent call last):
  File "/mnt/c/Users/Killua/Desktop/Vehicle-Inspection-Web-App-main/.venv/lib/python3.10/site-packages/flask/app.py", line 1473, in wsgi_app
    response = self.full_dispatch_request()
  File "/mnt/c/Users/Killua/Desktop/Vehicle-Inspection-Web-App-main/.venv/lib/python3.10/site-packages/flask/app.py", line 883, in full_dispatch_request
    return self.finalize_request(rv)
  File "/mnt/c/Users/Killua/Desktop/Vehicle-Inspection-Web-App-main/.venv/lib/python3.10/site-packages/flask/app.py", line 902, in finalize_request
    response = self.make_response(rv)
  File "/mnt/c/Users/Killua/Desktop/Vehicle-Inspection-Web-App-main/.venv/lib/python3.10/site-packages/flask/app.py", line 1174, in make_response
    raise TypeError(
TypeError: The view function for 'reports.add_report' did not return a valid response. The function either returned None or ended without a return statement.
2025-07-21 23:41:22,894 ERROR: Exception on /report/add [GET] [in /mnt/c/Users/Killua/Desktop/Vehicle-Inspection-Web-App-main/.venv/lib/python3.10/site-packages/flask/app.py:838]
Traceback (most recent call last):
  File "/mnt/c/Users/Killua/Desktop/Vehicle-Inspection-Web-App-main/.venv/lib/python3.10/site-packages/flask/app.py", line 1473, in wsgi_app
    response = self.full_dispatch_request()
  File "/mnt/c/Users/Killua/Desktop/Vehicle-Inspection-Web-App-main/.venv/lib/python3.10/site-packages/flask/app.py", line 883, in full_dispatch_request
    return self.finalize_request(rv)
  File "/mnt/c/Users/Killua/Desktop/Vehicle-Inspection-Web-App-main/.venv/lib/python3.10/site-packages/flask/app.py", line 902, in finalize_request
    response = self.make_response(rv)
  File "/mnt/c/Users/Killua/Desktop/Vehicle-Inspection-Web-App-main/.venv/lib/python3.10/site-packages/flask/app.py", line 1174, in make_response
    raise TypeError(
TypeError: The view function for 'reports.add_report' did not return a valid response. The function either returned None or ended without a return statement.
2025-07-21 23:41:29,183 ERROR: Exception on /report/add [GET] [in /mnt/c/Users/Killua/Desktop/Vehicle-Inspection-Web-App-main/.venv/lib/python3.10/site-packages/flask/app.py:838]
Traceback (most recent call last):
  File "/mnt/c/Users/Killua/Desktop/Vehicle-Inspection-Web-App-main/.venv/lib/python3.10/site-packages/flask/app.py", line 1473, in wsgi_app
    response = self.full_dispatch_request()
  File "/mnt/c/Users/Killua/Desktop/Vehicle-Inspection-Web-App-main/.venv/lib/python3.10/site-packages/flask/app.py", line 883, in full_dispatch_request
    return self.finalize_request(rv)
  File "/mnt/c/Users/Killua/Desktop/Vehicle-Inspection-Web-App-main/.venv/lib/python3.10/site-packages/flask/app.py", line 902, in finalize_request
    response = self.make_response(rv)
  File "/mnt/c/Users/Killua/Desktop/Vehicle-Inspection-Web-App-main/.venv/lib/python3.10/site-packages/flask/app.py", line 1174, in make_response
    raise TypeError(
TypeError: The view function for 'reports.add_report' did not return a valid response. The function either returned None or ended without a return statement.
2025-07-21 23:47:40,803 ERROR: Unhandled Exception: Could not build url for endpoint 'reports.add_report'. Did you mean 'reports.update_report' instead? [in /mnt/c/Users/Killua/Desktop/Vehicle-Inspection-Web-App-main/app/routes/errors.py:36]
2025-07-22 00:12:48,845 ERROR: Unhandled Exception: 'None' has no attribute 'id' [in /mnt/c/Users/Killua/Desktop/Vehicle-Inspection-Web-App-main/app/routes/errors.py:36]
2025-07-22 12:58:10,267 ERROR: Unhandled Exception: (sqlite3.OperationalError) no such column: expertise_reports.report_id
[SQL: SELECT expertise_reports.id AS expertise_reports_id, expertise_reports.report_id AS expertise_reports_report_id, expertise_reports.expertise_type_id AS expertise_reports_expertise_type_id, expertise_reports.comment AS expertise_reports_comment 
FROM expertise_reports 
WHERE expertise_reports.expertise_type_id IN (?, ?, ?)]
[parameters: (1, 2, 3)]
(Background on this error at: https://sqlalche.me/e/20/e3q8) [in /mnt/c/Users/Killua/Desktop/Vehicle-Inspection-Web-App-main/app/routes/errors.py:36]
2025-07-22 12:58:13,250 ERROR: Unhandled Exception: (sqlite3.OperationalError) no such column: expertise_reports.report_id
[SQL: SELECT expertise_reports.id AS expertise_reports_id, expertise_reports.report_id AS expertise_reports_report_id, expertise_reports.expertise_type_id AS expertise_reports_expertise_type_id, expertise_reports.comment AS expertise_reports_comment 
FROM expertise_reports 
WHERE expertise_reports.expertise_type_id IN (?)]
[parameters: (24,)]
(Background on this error at: https://sqlalche.me/e/20/e3q8) [in /mnt/c/Users/Killua/Desktop/Vehicle-Inspection-Web-App-main/app/routes/errors.py:36]
2025-07-22 13:07:33,446 ERROR: Unhandled Exception: (sqlite3.OperationalError) no such column: expertise_reports.report_id
[SQL: SELECT expertise_reports.id AS expertise_reports_id, expertise_reports.report_id AS expertise_reports_report_id, expertise_reports.expertise_type_id AS expertise_reports_expertise_type_id, expertise_reports.comment AS expertise_reports_comment 
FROM expertise_reports 
WHERE expertise_reports.expertise_type_id IN (?, ?, ?)]
[parameters: (1, 2, 3)]
(Background on this error at: https://sqlalche.me/e/20/e3q8) [in /mnt/c/Users/Killua/Desktop/Vehicle-Inspection-Web-App-main/app/routes/errors.py:36]
2025-07-22 13:08:08,691 ERROR: Unhandled Exception: (sqlite3.OperationalError) no such column: expertise_reports.report_id
[SQL: SELECT expertise_reports.id AS expertise_reports_id, expertise_reports.report_id AS expertise_reports_report_id, expertise_reports.expertise_type_id AS expertise_reports_expertise_type_id, expertise_reports.comment AS expertise_reports_comment 
FROM expertise_reports 
WHERE expertise_reports.expertise_type_id IN (?)]
[parameters: (24,)]
(Background on this error at: https://sqlalche.me/e/20/e3q8) [in /mnt/c/Users/Killua/Desktop/Vehicle-Inspection-Web-App-main/app/routes/errors.py:36]
2025-07-22 14:28:09,974 ERROR: Unhandled Exception: 'NoneType' object has no attribute 'name' [in /mnt/c/Users/Killua/Desktop/Vehicle-Inspection-Web-App-main/app/routes/errors.py:36]
2025-07-22 14:28:17,238 ERROR: Unhandled Exception: (sqlite3.OperationalError) no such table: package_content
[SQL: SELECT package_content.id AS package_content_id, package_content.package_id AS package_content_package_id, package_content.content_item AS package_content_content_item 
FROM package_content 
WHERE ? = package_content.package_id]
[parameters: (2,)]
(Background on this error at: https://sqlalche.me/e/20/e3q8) [in /mnt/c/Users/Killua/Desktop/Vehicle-Inspection-Web-App-main/app/routes/errors.py:36]
2025-07-22 14:28:34,488 ERROR: Unhandled Exception: (sqlite3.OperationalError) no such table: package_content
[SQL: SELECT package_content.id AS package_content_id, package_content.package_id AS package_content_package_id, package_content.content_item AS package_content_content_item 
FROM package_content 
WHERE ? = package_content.package_id]
[parameters: (2,)]
(Background on this error at: https://sqlalche.me/e/20/e3q8) [in /mnt/c/Users/Killua/Desktop/Vehicle-Inspection-Web-App-main/app/routes/errors.py:36]
2025-07-22 14:28:36,772 ERROR: Unhandled Exception: (sqlite3.OperationalError) no such table: package_content
[SQL: SELECT package_content.id AS package_content_id, package_content.package_id AS package_content_package_id, package_content.content_item AS package_content_content_item 
FROM package_content 
WHERE ? = package_content.package_id]
[parameters: (1,)]
(Background on this error at: https://sqlalche.me/e/20/e3q8) [in /mnt/c/Users/Killua/Desktop/Vehicle-Inspection-Web-App-main/app/routes/errors.py:36]
2025-07-22 15:28:52,637 ERROR: Unhandled Exception: settings/add_company.html [in /mnt/c/Users/Killua/Desktop/Vehicle-Inspection-Web-App-main/app/routes/errors.py:36]
